<?xml version="1.0"?><robot name="pepe">
	<link name="0">
		<visual>
			<geometry>
				<cylinder length="2.8311853483854614" radius="0.500874171129777"/>
			</geometry>
		</visual>
		<collision>
			<geometry>
				<cylinder length="2.8311853483854614" radius="0.500874171129777"/>
			</geometry>
		</collision>
		<inertial>
			<mass value="2.231389824638972"/>
			<inertia ixx="0.03" iyy="0.03" izz="0.03" ixy="0" ixz="0" iyz="0"/>
		</inertial>
	</link>
	<link name="11">
		<visual>
			<geometry>
				<cylinder length="2.0" radius="0.4"/>
			</geometry>
		</visual>
		<collision>
			<geometry>
				<cylinder length="2.0" radius="0.4"/>
			</geometry>
		</collision>
		<inertial>
			<mass value="1.0053096491487339"/>
			<inertia ixx="0.03" iyy="0.03" izz="0.03" ixy="0" ixz="0" iyz="0"/>
		</inertial>
	</link>
	<link name="12">
		<visual>
			<geometry>
				<cylinder length="2.0" radius="0.4"/>
			</geometry>
		</visual>
		<collision>
			<geometry>
				<cylinder length="2.0" radius="0.4"/>
			</geometry>
		</collision>
		<inertial>
			<mass value="1.0053096491487339"/>
			<inertia ixx="0.03" iyy="0.03" izz="0.03" ixy="0" ixz="0" iyz="0"/>
		</inertial>
	</link>
	<link name="23">
		<visual>
			<geometry>
				<cylinder length="2.792636573641017" radius="0.5261291923506857"/>
			</geometry>
		</visual>
		<collision>
			<geometry>
				<cylinder length="2.792636573641017" radius="0.5261291923506857"/>
			</geometry>
		</collision>
		<inertial>
			<mass value="2.428561427198704"/>
			<inertia ixx="0.03" iyy="0.03" izz="0.03" ixy="0" ixz="0" iyz="0"/>
		</inertial>
	</link>
	<link name="24">
		<visual>
			<geometry>
				<cylinder length="2.792636573641017" radius="0.5261291923506857"/>
			</geometry>
		</visual>
		<collision>
			<geometry>
				<cylinder length="2.792636573641017" radius="0.5261291923506857"/>
			</geometry>
		</collision>
		<inertial>
			<mass value="2.428561427198704"/>
			<inertia ixx="0.03" iyy="0.03" izz="0.03" ixy="0" ixz="0" iyz="0"/>
		</inertial>
	</link>
	<joint name="11_to_0" type="revolute">
		<parent link="0"/>
		<child link="11"/>
		<axis xyz="4.084096239170562e-05 0.5769514991748521 0.8167784068717208"/>
		<limit effort="500" upper="3.1415" lower="-3.1415" velocity="10"/>
		<origin rpy="4.5018264570184305 0.0001 0.14595201676540442" xyz="0.4436498960577428 0.5498169709522223 0.31399830293585507"/>
	</joint>
	<joint name="12_to_0" type="revolute">
		<parent link="0"/>
		<child link="12"/>
		<axis xyz="4.084096239170562e-05 0.5769514991748521 0.8167784068717208"/>
		<limit effort="500" upper="3.1415" lower="-3.1415" velocity="10"/>
		<origin rpy="6.752739685527645 0.0001 0.14595201676540442" xyz="0.4436498960577428 0.5498169709522223 0.31399830293585507"/>
	</joint>
	<joint name="23_to_0" type="revolute">
		<parent link="0"/>
		<child link="23"/>
		<axis xyz="4.584302288018976e-05 0.7768638297363605 0.6296686334460155"/>
		<limit effort="500" upper="3.1415" lower="-3.1415" velocity="10"/>
		<origin rpy="4.8532221090884855 3.048838940012898 3.29386847740449" xyz="0.4905666926428531 0.33411710766608765 0.4151071715514625"/>
	</joint>
	<joint name="24_to_0" type="revolute">
		<parent link="0"/>
		<child link="24"/>
		<axis xyz="4.584302288018976e-05 0.7768638297363605 0.6296686334460155"/>
		<limit effort="500" upper="3.1415" lower="-3.1415" velocity="10"/>
		<origin rpy="6.066527636360607 3.048838940012898 3.29386847740449" xyz="0.4905666926428531 0.33411710766608765 0.4151071715514625"/>
	</joint>
</robot>
